Workbook

Sheet Tableau de bord
B2: COSITI — SUIVI DES ADHÉSIONS ET DES COTISATIONS
B3: Coopérative du Secteur Informel et des Travailleurs Indépendants
B4: Tableau de bord — se met à jour automatiquement à partir des feuilles "Adhérents" et "Paiements"
B6: Nombre d'adhérents enregistrés | D6: =COUNTIF(Adhérents!B3:B202,"?*") -> 172
B7: Adhérents ayant au moins une cotisation | D7: =COUNTIFS(Adhérents!B3:B202,"?*",Adhérents!G3:G202,">0") -> 57
B8: Adhérents sans cotisation enregistrée | D8: =D6-D7 -> 115
B9: Adhérents à déclarer à la CNPS | D9: =COUNTIF(Adhérents!H3:H202,"À déclarer") -> 29
B10: % adhérents sans cotisation | D10: =IFERROR(D8/D6,0) -> 0.66860465
B12: Recettes d'inscription | D12: =SUM(Adhérents!F3:F202) -> 172000
B13: Total des cotisations perçues | D13: =SUM(Paiements!C3:C506) -> 1305700
B15: TOTAL GÉNÉRAL (inscriptions + cotisations) | D15: =D12+D13 -> 1477700
B18: Cumul des cotisations des adhérents à déclarer CNPS | D18: =SUMIF(Adhérents!H3:H202,"À déclarer",Adhérents!G3:G202) -> 1160000
B20: Seuil de déclaration CNPS en vigueur (paramètre) | D20: =Paramètres!C5 -> 15000
B23: Pour ajouter, modifier ou supprimer un adhérent ou une cotisation : voir l'onglet "Mode d'emploi".

Sheet Paramètres
B2: PARAMÈTRES GÉNÉRAUX
B4: Montant de l'inscription | C4: 1000 | D4: Utilisé automatiquement dans la feuille "Adhérents". Modifiez cette cellule pour changer le montant partout.
B5: Seuil de déclaration CNPS | C5: 15000 | D5: Cumul de cotisation à partir duquel un adhérent doit être déclaré à la CNPS. Estimé à partir des données transmises (dernier cas non déclaré : 16 500 F ; premier cas déclaré : 17 700 F) — à corriger si un seuil réglementaire précis est disponible.
B7: LÉGENDE DES COULEURS
C8: Cellule à saisir ou modifier (donnée d'entrée)
C9: Cellule calculée automatiquement — ne pas modifier
C10: Alerte : adhérent à déclarer à la CNPS

Sheet Adhérents
A1: ADHÉRENTS — LISTE ET COTISATIONS CUMULÉES
A2: N° | B2: Nom de l'adhérent | C2: Contact (optionnel) | D2: Date d'inscription | E2: Inscription payée (Oui/Non) | F2: Montant inscription | G2: Cotisation cumulée | H2: Statut CNPS | I2: Date déclaration CNPS
A3: =IF(B3="","",ROW()-2) -> 1 | B3: NCHARE ISSOFA | C3: 699897937 | D3: 24/07/2026 | E3: Oui | F3: =IF(E3="Oui",Paramètres!$C$4,0) -> 1000 | G3: =IF(B3="","",SUMIF(Paiements!$B$3:$B$506,B3,Paiements!$C$3:$C$506)) -> 42000 | H3: =IF(B3="","",IF(G3>=Paramètres!$C$5,"À déclarer","—")) -> À déclarer | I3: 46231
A4: =IF(B4="","",ROW()-2) -> 2 | B4: SOUAÏBOU OUSMAILA | C4: 697875141 | D4: 24/07/2026 | E4: Oui | F4: =IF(E4="Oui",Paramètres!$C$4,0) -> 1000 | G4: =IF(B4="","",SUMIF(Paiements!$B$3:$B$506,B4,Paiements!$C$3:$C$506)) -> 49300 | H4: =IF(B4="","",IF(G4>=Paramètres!$C$5,"À déclarer","—")) -> À déclarer | I4: 46219
A5: =IF(B5="","",ROW()-2) -> 3 | B5: YOUGOUTA | D5: 24/07/2026 | E5: Oui | F5: =IF(E5="Oui",Paramètres!$C$4,0) -> 1000 | G5: =IF(B5="","",SUMIF(Paiements!$B$3:$B$506,B5,Paiements!$C$3:$C$506)) -> 4900 | H5: =IF(B5="","",IF(G5>=Paramètres!$C$5,"À déclarer","—")) -> —
A6: =IF(B6="","",ROW()-2) -> 4 | B6: KUETCHE | C6: 655007836 | D6: 24/07/2026 | E6: Oui | F6: =IF(E6="Oui",Paramètres!$C$4,0) -> 1000 | G6: =IF(B6="","",SUMIF(Paiements!$B$3:$B$506,B6,Paiements!$C$3:$C$506)) -> 106000 | H6: =IF(B6="","",IF(G6>=Paramètres!$C$5,"À déclarer","—")) -> À déclarer | I6: 46231
A7: =IF(B7="","",ROW()-2) -> 5 | B7: BOUBA YOUNOUSSA | C7: 655005983 | D7: 24/07/2026 | E7: Oui | F7: =IF(E7="Oui",Paramètres!$C$4,0) -> 1000 | G7: =IF(B7="","",SUMIF(Paiements!$B$3:$B$506,B7,Paiements!$C$3:$C$506)) -> 17700 | H7: =IF(B7="","",IF(G7>=Paramètres!$C$5,"À déclarer","—")) -> À déclarer | I7: 46231
A8: =IF(B8="","",ROW()-2) -> 6 | B8: KAMENI DENGA | C8: 699433680 | D8: 24/07/2026 | E8: Oui | F8: =IF(E8="Oui",Paramètres!$C$4,0) -> 1000 | G8: =IF(B8="","",SUMIF(Paiements!$B$3:$B$506,B8,Paiements!$C$3:$C$506)) -> 24400 | H8: =IF(B8="","",IF(G8>=Paramètres!$C$5,"À déclarer","—")) -> À déclarer | I8: 46231
A9: =IF(B9="","",ROW()-2) -> 7 | B9: MOHAMED MAMOUDOU | C9: 681506550 | D9: 24/07/2026 | E9: Oui | F9: =IF(E9="Oui",Paramètres!$C$4,0) -> 1000 | G9: =IF(B9="","",SUMIF(Paiements!$B$3:$B$506,B9,Paiements!$C$3:$C$506)) -> 48000 | H9: =IF(B9="","",IF(G9>=Paramètres!$C$5,"À déclarer","—")) -> À déclarer | I9: 46231
A10: =IF(B10="","",ROW()-2) -> 8 | B10: DEZO TELIABOU | D10: 24/07/2026 | E10: Oui | F10: =IF(E10="Oui",Paramètres!$C$4,0) -> 1000 | G10: =IF(B10="","",SUMIF(Paiements!$B$3:$B$506,B10,Paiements!$C$3:$C$506)) -> 4900 | H10: =IF(B10="","",IF(G10>=Paramètres!$C$5,"À déclarer","—")) -> —
A11: =IF(B11="","",ROW()-2) -> 9 | B11: GONDJI MAMADOU | C11: 698099956 | D11: 24/07/2026 | E11: Oui | F11: =IF(E11="Oui",Paramètres!$C$4,0) -> 1000 | G11: =IF(B11="","",SUMIF(Paiements!$B$3:$B$506,B11,Paiements!$C$3:$C$506)) -> 6000 | H11: =IF(B11="","",IF(G11>=Paramètres!$C$5,"À déclarer","—")) -> —
A12: =IF(B12="","",ROW()-2) -> 10 | B12: CHO RUBEN | C12: 651486286 | D12: 24/07/2026 | E12: Oui | F12: =IF(E12="Oui",Paramètres!$C$4,0) -> 1000 | G12: =IF(B12="","",SUMIF(Paiements!$B$3:$B$506,B12,Paiements!$C$3:$C$506)) -> 18000 | H12: =IF(B12="","",IF(G12>=Paramètres!$C$5,"À déclarer","—")) -> À déclarer
A13: =IF(B13="","",ROW()-2) -> 11 | B13: BIKIE MARGUERITE | C13: 675513127 | D13: 24/07/2026 | E13: Oui | F13: =IF(E13="Oui",Paramètres!$C$4,0) -> 1000 | G13: =IF(B13="","",SUMIF(Paiements!$B$3:$B$506,B13,Paiements!$C$3:$C$506)) -> 7700 | H13: =IF(B13="","",IF(G13>=Paramètres!$C$5,"À déclarer","—")) -> —
A14: =IF(B14="","",ROW()-2) -> 12 | B14: MBESSOLOKO NADEGE | D14: 24/07/2026 | E14: Oui | F14: =IF(E14="Oui",Paramètres!$C$4,0) -> 1000 | G14: =IF(B14="","",SUMIF(Paiements!$B$3:$B$506,B14,Paiements!$C$3:$C$506)) -> 0 | H14: =IF(B14="","",IF(G14>=Paramètres!$C$5,"À déclarer","—")) -> —
A15: =IF(B15="","",ROW()-2) -> 13 | B15: LEGNYUY MONTONG | C15: 673170372 | D15: 24/07/2026 | E15: Oui | F15: =IF(E15="Oui",Paramètres!$C$4,0) -> 1000 | G15: =IF(B15="","",SUMIF(Paiements!$B$3:$B$506,B15,Paiements!$C$3:$C$506)) -> 63000 | H15: =IF(B15="","",IF(G15>=Paramètres!$C$5,"À déclarer","—")) -> À déclarer | I15: 46231
A16: =IF(B16="","",ROW()-2) -> 14 | B16: FOSSO COLETTE | D16: 24/07/2026 | E16: Oui | F16: =IF(E16="Oui",Paramètres!$C$4,0) -> 1000 | G16: =IF(B16="","",SUMIF(Paiements!$B$3:$B$506,B16,Paiements!$C$3:$C$506)) -> 700 | H16: =IF(B16="","",IF(G16>=Paramètres!$C$5,"À déclarer","—")) -> —
A17: =IF(B17="","",ROW()-2) -> 15 | B17: MATEKEM TAKAM | D17: 24/07/2026 | E17: Oui | F17: =IF(E17="Oui",Paramètres!$C$4,0) -> 1000 | G17: =IF(B17="","",SUMIF(Paiements!$B$3:$B$506,B17,Paiements!$C$3:$C$506)) -> 7700 | H17: =IF(B17="","",IF(G17>=Paramètres!$C$5,"À déclarer","—")) -> —
A18: =IF(B18="","",ROW()-2) -> 16 | B18: BEFOLO RAISSA | D18: 24/07/2026 | E18: Oui | F18: =IF(E18="Oui",Paramètres!$C$4,0) -> 1000 | G18: =IF(B18="","",SUMIF(Paiements!$B$3:$B$506,B18,Paiements!$C$3:$C$506)) -> 60000 | H18: =IF(B18="","",IF(G18>=Paramètres!$C$5,"À déclarer","—")) -> À déclarer | I18: 46233
A19: =IF(B19="","",ROW()-2) -> 17 | B19: MAMIAFO CLEMENCE | D19: 24/07/2026 | E19: Oui | F19: =IF(E19="Oui",Paramètres!$C$4,0) -> 1000 | G19: =IF(B19="","",SUMIF(Paiements!$B$3:$B$506,B19,Paiements!$C$3:$C$506)) -> 63000 | H19: =IF(B19="","",IF(G19>=Paramètres!$C$5,"À déclarer","—")) -> À déclarer | I19: 46237
A20: =IF(B20="","",ROW()-2) -> 18 | B20: NGON MBASSA | C20: 697359841 | D20: 24/07/2026 | E20: Oui | F20: =IF(E20="Oui",Paramètres!$C$4,0) -> 1000 | G20: =IF(B20="","",SUMIF(Paiements!$B$3:$B$506,B20,Paiements!$C$3:$C$506)) -> 14900 | H20: =IF(B20="","",IF(G20>=Paramètres!$C$5,"À déclarer","—")) -> —
A21: =IF(B21="","",ROW()-2) -> 19 | B21: ZANG ZANG LUC | C21: 697015774 | D21: 24/07/2026 | E21: Oui | F21: =IF(E21="Oui",Paramètres!$C$4,0) -> 1000 | G21: =IF(B21="","",SUMIF(Paiements!$B$3:$B$506,B21,Paiements!$C$3:$C$506)) -> 24000 | H21: =IF(B21="","",IF(G21>=Paramètres!$C$5,"À déclarer","—")) -> À déclarer
A22: =IF(B22="","",ROW()-2) -> 20 | B22: DIKIDALA | C22: 686550099 | D22: 24/07/2026 | E22: Oui | F22: =IF(E22="Oui",Paramètres!$C$4,0) -> 1000 | G22: =IF(B22="","",SUMIF(Paiements!$B$3:$B$506,B22,Paiements!$C$3:$C$506)) -> 5000 | H22: =IF(B22="","",IF(G22>=Paramètres!$C$5,"À déclarer","—")) -> —
A23: =IF(B23="","",ROW()-2) -> 21 | B23: TOUKSI TSEME LEOPOLD | C23: 655710741 | D23: 24/07/2026 | E23: Oui | F23: =IF(E23="Oui",Paramètres!$C$4,0) -> 1000 | G23: =IF(B23="","",SUMIF(Paiements!$B$3:$B$506,B23,Paiements!$C$3:$C$506)) -> 69000 | H23: =IF(B23="","",IF(G23>=Paramètres!$C$5,"À déclarer","—")) -> À déclarer | I23: 46231
A24: =IF(B24="","",ROW()-2) -> 22 | B24: SIPOWA CYRIEN | C24: 697074556 | D24: 24/07/2026 | E24: Oui | F24: =IF(E24="Oui",Paramètres!$C$4,0) -> 1000 | G24: =IF(B24="","",SUMIF(Paiements!$B$3:$B$506,B24,Paiements!$C$3:$C$506)) -> 13000 | H24: =IF(B24="","",IF(G24>=Paramètres!$C$5,"À déclarer","—")) -> —
A25: =IF(B25="","",ROW()-2) -> 23 | B25: MBENTY OLAMA L. | D25: 24/07/2026 | E25: Oui | F25: =IF(E25="Oui",Paramètres!$C$4,0) -> 1000 | G25: =IF(B25="","",SUMIF(Paiements!$B$3:$B$506,B25,Paiements!$C$3:$C$506)) -> 1000 | H25: =IF(B25="","",IF(G25>=Paramètres!$C$5,"À déclarer","—")) -> —
A26: =IF(B26="","",ROW()-2) -> 24 | B26: EDAMA MENGUE CLAUDE | D26: 24/07/2026 | E26: Oui | F26: =IF(E26="Oui",Paramètres!$C$4,0) -> 1000 | G26: =IF(B26="","",SUMIF(Paiements!$B$3:$B$506,B26,Paiements!$C$3:$C$506)) -> 1000 | H26: =IF(B26="","",IF(G26>=Paramètres!$C$5,"À déclarer","—")) -> —
A27: =IF(B27="","",ROW()-2) -> 25 | B27: NOMO JACQUES | D27: 24/07/2026 | E27: Oui | F27: =IF(E27="Oui",Paramètres!$C$4,0) -> 1000 | G27: =IF(B27="","",SUMIF(Paiements!$B$3:$B$506,B27,Paiements!$C$3:$C$506)) -> 51000 | H27: =IF(B27="","",IF(G27>=Paramètres!$C$5,"À déclarer","—")) -> À déclarer | I27: 46231
A28: =IF(B28="","",ROW()-2) -> 26 | B28: NDI THERESE | C28: 694381643 | D28: 24/07/2026 | E28: Oui | F28: =IF(E28="Oui",Paramètres!$C$4,0) -> 1000 | G28: =IF(B28="","",SUMIF(Paiements!$B$3:$B$506,B28,Paiements!$C$3:$C$506)) -> 1000 | H28: =IF(B28="","",IF(G28>=Paramètres!$C$5,"À déclarer","—")) -> —
A29: =IF(B29="","",ROW()-2) -> 27 | B29: NGONDI BRIGITTE | D29: 24/07/2026 | E29: Oui | F29: =IF(E29="Oui",Paramètres!$C$4,0) -> 1000 | G29: =IF(B29="","",SUMIF(Paiements!$B$3:$B$506,B29,Paiements!$C$3:$C$506)) -> 4500 | H29: =IF(B29="","",IF(G29>=Paramètres!$C$5,"À déclarer","—")) -> —
A30: =IF(B30="","",ROW()-2) -> 28 | B30: KOUNOU MBEGA | D30: 24/07/2026 | E30: Oui | F30: =IF(E30="Oui",Paramètres!$C$4,0) -> 1000 | G30: =IF(B30="","",SUMIF(Paiements!$B$3:$B$506,B30,Paiements!$C$3:$C$506)) -> 1000 | H30: =IF(B30="","",IF(G30>=Paramètres!$C$5,"À déclarer","—")) -> —
A31: =IF(B31="","",ROW()-2) -> 29 | B31: OWONA EKOUDI MONIQUE | C31: 679731587 | D31: 24/07/2026 | E31: Oui | F31: =IF(E31="Oui",Paramètres!$C$4,0) -> 1000 | G31: =IF(B31="","",SUMIF(Paiements!$B$3:$B$506,B31,Paiements!$C$3:$C$506)) -> 18000 | H31: =IF(B31="","",IF(G31>=Paramètres!$C$5,"À déclarer","—")) -> À déclarer
A32: =IF(B32="","",ROW()-2) -> 30 | B32: TINA TONTON AUGUSTE | D32: 24/07/2026 | E32: Oui | F32: =IF(E32="Oui",Paramètres!$C$4,0) -> 1000 | G32: =IF(B32="","",SUMIF(Paiements!$B$3:$B$506,B32,Paiements!$C$3:$C$506)) -> 66300 | H32: =IF(B32="","",IF(G32>=Paramètres!$C$5,"À déclarer","—")) -> À déclarer | I32: 46233
A33: =IF(B33="","",ROW()-2) -> 31 | B33: ESSOLA AHANDA | D33: 24/07/2026 | E33: Oui | F33: =IF(E33="Oui",Paramètres!$C$4,0) -> 1000 | G33: =IF(B33="","",SUMIF(Paiements!$B$3:$B$506,B33,Paiements!$C$3:$C$506)) -> 16500 | H33: =IF(B33="","",IF(G33>=Paramètres!$C$5,"À déclarer","—")) -> À déclarer | I33: 46219
A34: =IF(B34="","",ROW()-2) -> 32 | B34: MESSEGO MEGANE C. | C34: 698768267 | D34: 24/07/2026 | E34: Oui | F34: =IF(E34="Oui",Paramètres!$C$4,0) -> 1000 | G34: =IF(B34="","",SUMIF(Paiements!$B$3:$B$506,B34,Paiements!$C$3:$C$506)) -> 42000 | H34: =IF(B34="","",IF(G34>=Paramètres!$C$5,"À déclarer","—")) -> À déclarer | I34: 46230
A35: =IF(B35="","",ROW()-2) -> 33 | B35: TIODJOU VANESSA | C35: 671679343 | D35: 24/07/2026 | E35: Oui | F35: =IF(E35="Oui",Paramètres!$C$4,0) -> 1000 | G35: =IF(B35="","",SUMIF(Paiements!$B$3:$B$506,B35,Paiements!$C$3:$C$506)) -> 42000 | H35: =IF(B35="","",IF(G35>=Paramètres!$C$5,"À déclarer","—")) -> À déclarer | I35: 46226
A36: 34 | B36: MAGNE FOPOSSI | D36: 24/07/2026 | E36: Oui | F36: =IF(E36="Oui",Paramètres!$C$4,0) -> 1000 | G36: =IF(B36="","",SUMIF(Paiements!$B$3:$B$506,B36,Paiements!$C$3:$C$506)) -> 1400 | H36: =IF(B36="","",IF(G36>=Paramètres!$C$5,"À déclarer","—")) -> —
A37: =IF(B37="","",ROW()-2) -> 35 | B37: TEUNYA MBATKAM | C37: 699872831 | D37: 24/07/2026 | E37: Oui | F37: =IF(E37="Oui",Paramètres!$C$4,0) -> 1000 | G37: =IF(B37="","",SUMIF(Paiements!$B$3:$B$506,B37,Paiements!$C$3:$C$506)) -> 40900 | H37: =IF(B37="","",IF(G37>=Paramètres!$C$5,"À déclarer","—")) -> À déclarer | I37: 46231
A38: =IF(B38="","",ROW()-2) -> 36 | B38: MBARGA JOSEPH | D38: 24/07/2026 | E38: Oui | F38: =IF(E38="Oui",Paramètres!$C$4,0) -> 1000 | G38: =IF(B38="","",SUMIF(Paiements!$B$3:$B$506,B38,Paiements!$C$3:$C$506)) -> 23400 | H38: =IF(B38="","",IF(G38>=Paramètres!$C$5,"À déclarer","—")) -> À déclarer | I38: 46231
A39: =IF(B39="","",ROW()-2) -> 37 | B39: MONABANG | D39: 24/07/2026 | E39: Oui | F39: =IF(E39="Oui",Paramètres!$C$4,0) -> 1000 | G39: =IF(B39="","",SUMIF(Paiements!$B$3:$B$506,B39,Paiements!$C$3:$C$506)) -> 32500 | H39: =IF(B39="","",IF(G39>=Paramètres!$C$5,"À déclarer","—")) -> À déclarer | I39: 46231
A40: 38 | B40: TCHAPHOU MAGLOIRE | D40: 24/07/2026 | E40: Oui | F40: =IF(E40="Oui",Paramètres!$C$4,0) -> 1000 | G40: =IF(B40="","",SUMIF(Paiements!$B$3:$B$506,B40,Paiements!$C$3:$C$506)) -> 1000 | H40: =IF(B40="","",IF(G40>=Paramètres!$C$5,"À déclarer","—")) -> —
...

Sheet Paiements
A1: PAIEMENTS DE COTISATIONS — JOURNAL DES VERSEMENTS
A2: Date | B2: Nom de l'adhérent | C2: Montant versé | D2: Mode de paiement | E2: Observations
A3: 24/07/2026 | B3: NCHARE ISSOFA | C3: 9900 | D3: Non précisé | E3: Cumul repris du rapport financier du 24/07/2026
A4: 24/07/2026 | B4: SOUAÏBOU OUSMAILA | C4: 24800 | D4: Non précisé | E4: Cumul repris du rapport financier du 24/07/2026
A5: 24/07/2026 | B5: YOUGOUTA | C5: 4900 | D5: Non précisé | E5: Cumul repris du rapport financier du 24/07/2026
A6: 24/07/2026 | B6: KUETCHE | C6: 54000 | D6: Non précisé | E6: Cumul repris du rapport financier du 24/07/2026
A7: 24/07/2026 | B7: BOUBA YOUNOUSSA | C7: 17700 | D7: Non précisé | E7: Cumul repris du rapport financier du 24/07/2026
A8: 24/07/2026 | B8: KAMENI DENGA | C8: 9100 | D8: Non précisé | E8: Cumul repris du rapport financier du 24/07/2026
A9: 24/07/2026 | B9: MOHAMED MAMOUDOU | C9: 28000 | D9: Non précisé | E9: Cumul repris du rapport financier du 24/07/2026
A10: 24/07/2026 | B10: DEZO TELIABOU | C10: 4900 | D10: Non précisé | E10: Cumul repris du rapport financier du 24/07/2026
A11: 24/07/2026 | B11: GONDJI MAMADOU | C11: 1000 | D11: Non précisé | E11: Cumul repris du rapport financier du 24/07/2026
A12: 24/07/2026 | B12: CHO RUBEN | C12: 6000 | D12: Non précisé | E12: Cumul repris du rapport financier du 24/07/2026
A13: 24/07/2026 | B13: BIKIE MARGUERITE | C13: 4000 | D13: Non précisé | E13: Cumul repris du rapport financier du 24/07/2026
A14: 24/07/2026 | B14: MBOLE CLEMENTINE | C14: 1000 | D14: Non précisé | E14: Cumul repris du rapport financier du 24/07/2026
... A40: 24/07/2026 | B40: MEKOUI NKODO MIREILLE | C40: 8000 | D40: Non précisé | E40: Cumul repris du rapport financier du 24/07/2026
A41: 46227 | B41: DONSA NELSON | C41: 3500 | D41: Orange Money
A42: 24/07/2026 | B42: YAKANA | C42: 1000 | D42: Non précisé | E42: Cumul repris du rapport financier du 24/07/2026
A43: 24/07/2027 | B43: CHO RUBEN | C43: 1000 | D43: Orange Money
A44: 46228 | B44: TINA TONTON AUGUSTE | C44: 3000 | D44: Orange Money
A45: 46229 | B45: YAKANA | C45: 4000 | D45: Orange Money | E45: Pour regularisation par RAF
A46: 46230 | B46: TOUKSI TSEME LEOPOLD | C46: 5000 | D46: Orange Money
A47: 46230 | B47: NOMO JACQUES | C47: 1000 | D47: Espèces
A48: 46232 | B48: NOMO JACQUES | C48: 6000 | D48: Espèces
A49: 46232 | B49: NGONDI BRIGITTE | C49: 1000 | D49: Espèces
A50: 46232 | B50: TINA TONTON AUGUSTE | C50: 4000 | D50: Orange Money
A51: 46232 | B51: ONDOA NGONDI | C51: 1000 | D51: Espèces
A52: 46232 | B52: MONABANG | C52: 4000 | D52: Espèces
A53: 46232 | B53: AMOUGOU NKOLO | C53: 15000 | D53: Espèces
A54: 46232 | B54: MEKOUI NKODO MIREILLE | C54: 7000 | D54: Orange Money
A55: 46232 | B55: YAKANA | C55: 2000 | D55: Orange Money | E55: POUR REGULARISATION DE 1000
A56: 46232 | B56: BEFOLO RAISSA | C56: 15000 | D56: Espèces
A57: 46232 | B57: BEYALA ONDOA | C57: 16000 | D57: Espèces
A58: 46233 | B58: MOHAMED MAMOUDOU | C58: 2000 | D58: Orange Money
A59: 46233 | B59: NGON MBASSA | C59: 5000 | D59: Espèces
A60: 46233 | B60: MABACOU SOLANGE | C60: 30000 | D60: Espèces
A61: 46233 | B61: LEGNYUY MONTONG | C61: 8000 | D61: Espèces
A62: 46234 | B62: YAKANA | C62: 1000 | D62: Orange Money
A63: 46234 | B63: KAMENI DENGA | C63: 4900 | D63: Orange Money
A64: 46234 | B64: BEFOLO RAISSA | C64: 5000 | D64: Espèces
A65: 46235 | B65: SIPOWA CYRIEN | C65: 5000 | D65: Orange Money
...

Sheet Mode d'emploi
B2: MODE D'EMPLOI
B4: Structure du classeur
B5: • "Adhérents" — un adhérent par ligne : identité, inscription, et cotisation cumulée calculée automatiquement.
B7: • "Paiements" — un versement de cotisation par ligne. Un même adhérent peut apparaître sur plusieurs lignes (plusieurs paiements dans le temps).
B9: • "Tableau de bord" — indicateurs calculés automatiquement à partir des deux feuilles ci-dessus.
B11: • "Paramètres" — montant d'inscription et seuil CNPS, modifiables en un seul endroit.
B13: Ajouter un adhérent — Dans "Adhérents", allez à la première ligne vide et saisissez son nom (colonne B). Les colonnes N°, Montant inscription, Cotisation cumulée et Statut CNPS se calculent seules. Complétez éventuellement le contact, la date d'inscription et "Inscription payée" (Oui/Non).
B15: Supprimer un adhérent — Sélectionnez sa ligne dans "Adhérents" (clic droit sur le numéro de ligne) puis "Supprimer". Pensez à supprimer aussi ses lignes correspondantes dans "Paiements" si vous ne voulez plus les compter.
B17: Ajouter / mettre à jour une cotisation — Dans "Paiements", ajoutez une nouvelle ligne : Date, Nom (liste déroulante reliée à "Adhérents"), Montant, Mode de paiement. La cotisation cumulée de l'adhérent se met à jour automatiquement dans "Adhérents".
B19: Corriger une cotisation — Modifiez simplement le montant sur la ligne concernée dans "Paiements".
B21: Supprimer une cotisation — Supprimez la ligne correspondante dans "Paiements".
B23: Suivi CNPS — La colonne "Statut CNPS" de "Adhérents" passe automatiquement à "À déclarer" (ligne surlignée en rouge) dès que le cumul de cotisation d'un adhérent atteint le seuil défini dans "Paramètres".
B25: Remarque sur les données initiales — Les 39 adhérents nommés reprennent l'état détaillé du rapport financier du 24/07/2026. Les 109 lignes "Adhérent à compléter n°..." représentent les autres adhérents déjà enregistrés (148 au total) dont le détail nominatif n'avait pas encore été transmis : remplacez ces libellés par les vrais noms au fur et à mesure de leur réception.
